Workbook

Sheet Sheet1
B1: PO | C1: ARTICLE | D1: QTY ORDER | E1: MARKET | F1: CUSTOMER | G1: WAREHOUSE | H1: START IN FG | I1: PO# CLOSING DATE | J1: SI DATE | K1: TOTAL PAIRS | L1: TOTAL CTN | M1: NO. CTN
A2: =+B2&B2 -> 78650397865039 | B2: 7865039 | C2: M997H2HN-D | D2: 1092 | E2: UNITED KINGDOM | F2: DSV SOLUTIONS LTD | G2: Factory Outlet Stock (UZ) | H2: 46238 | K2: 216 | L2: =+COUNT(M2:FC2) -> 18 | M2: 31 | N2: 32 | O2: 36 | P2: 40 | Q2: 44 | R2: 46 | S2: 49 | T2: 50 | U2: 51 | V2: 56 | W2: 57 | X2: 58 | Y2: 64 | Z2: 65 | AA2: 66 | AB2: 70 | AC2: 71 | AD2: 78
A3: =+B3&B3 -> 78650467865046 | B3: 7865046 | C3: M997H2HN-D | D3: 4284 | E3: NETHERLANDS | F3: DSV VENLO | G3: Factory Outlet Stock (VZ) | H3: 46230 | K3: 168 | L3: =+COUNT(M3:FC3) -> 14 | M3: 199 | N3: 225 | O3: 259 | P3: 260 | Q3: 283 | R3: 285 | S3: 304 | T3: 306 | U3: 316 | V3: 317 | W3: 319 | X3: 333 | Y3: 342 | Z3: 343
A4: =+B4&B4 -> 78650477865047 | B4: 7865047 | C4: CM997HLP-D | D4: 3012 | E4: NETHERLANDS | F4: DSV VENLO | G4: Factory Outlet Stock (VZ) | H4: 46237 | K4: 288 | L4: =+COUNT(M4:FC4) -> 24 | M4: 47 | N4: 71 | O4: 72 | P4: 73 | Q4: 74 | R4: 79 | S4: 100 | T4: 101 | U4: 137 | V4: 138 | W4: 168 | X4: 169 | Y4: 170 | Z4: 172 | AA4: 194 | AB4: 195 | AC4: 196 | AD4: 197 | AE4: 198 | AF4: 199 | AG4: 200 | AH4: 216 | AI4: 231 | AJ4: 232
A5: =+B5&B5 -> 78661897866189 | B5: 7866189 | C5: GC574EVK-M | D5: 360 | E5: POLAND | F5: NEW BALANCE POLAND SP ZOO | G5: Direct Rotterdam (RTM) (DR) | H5: 46237 | K5: 318 | L5: =+COUNT(M5:FC5) -> 27 | M5: 2 | N5: 3 | O5: 4 | P5: 5 | Q5: 6 | R5: 7 | S5: 9 | T5: 10 | U5: 11 | V5: 12 | W5: 13 | X5: 14 | Y5: 15 | Z5: 16 | AA5: 17 | AB5: 18 | AC5: 19 | AD5: 20 | AE5: 21 | AF5: 22 | AG5: 23 | AH5: 25 | AI5: 26 | AJ5: 27 | AK5: 28 | AL5: 29 | AM5: 30
A6: =+B6&B6 -> 78662127866212 | B6: 7866212 | C6: GC574EVB-M | D6: 270 | E6: POLAND | F6: NEW BALANCE POLAND SP ZOO | G6: Direct Rotterdam (RTM) (DR) | H6: 46234 | I6: 46238 | J6: 46238 | K6: 234 | L6: =+COUNT(M6:FC6) -> 21 | M6: 1 | N6: 2 | O6: 3 | P6: 4 | Q6: 5 | R6: 6 | S6: 7 | T6: 8 | U6: 9 | V6: 11 | W6: 12 | X6: 13 | Y6: 15 | Z6: 16 | AA6: 17 | AB6: 19 | AC6: 20 | AD6: 21 | AE6: 22 | AF6: 23 | AG6: 24
A7: =+B7&B7 -> 78662257866225 | B7: 7866225 | C7: GC574EVG-M | D7: 234 | E7: POLAND | F7: NEW BALANCE POLAND SP ZOO | G7: Direct Rotterdam (RTM) (DR) | H7: 46237 | K7: 198 | L7: =+COUNT(M7:FC7) -> 18 | M7: 2 | N7: 4 | O7: 5 | P7: 6 | Q7: 7 | R7: 8 | S7: 9 | T7: 10 | U7: 11 | V7: 12 | W7: 13 | X7: 14 | Y7: 15 | Z7: 16 | AA7: 17 | AB7: 18 | AC7: 20 | AD7: 21
A8: =+B8&B8 -> 78662397866239 | B8: 7866239 | C8: GC574EVE-M | D8: 234 | E8: POLAND | F8: NEW BALANCE POLAND SP ZOO | G8: Direct Rotterdam (RTM) (DR) | H8: 46234 | K8: 72 | L8: =+COUNT(M8:FC8) -> 6 | M8: 2 | N8: 4 | O8: 6 | P8: 11 | Q8: 13 | R8: 16
A9: =+B9&B9 -> 78662437866243 | B9: 7866243 | C9: GC574EVW-M | D9: 144 | E9: POLAND | F9: NEW BALANCE POLAND SP ZOO | G9: Direct Rotterdam (RTM) (DR) | H9: 46237 | K9: 114 | L9: =+COUNT(M9:FC9) -> 10 | M9: 1 | N9: 2 | O9: 3 | P9: 4 | Q9: 6 | R9: 7 | S9: 8 | T9: 9 | U9: 11 | V9: 13
A10: =+B10&B10 -> 78662527866252 | B10: 7866252 | C10: PV574EVG-M | D10: 144 | E10: POLAND | F10: NEW BALANCE POLAND SP ZOO | G10: Direct Rotterdam (RTM) (DR) | H10: 46239 | K10: 24 | L10: =+COUNT(M10:FC10) -> 2 | M10: 6 | N10: 10
A11: =+B11&B11 -> 78664367866436 | B11: 7866436 | C11: GC9060GY-M | D11: 3570 | E11: ITALY | F11: NEW BALANCE ITALY SRL | G11: Direct Rotterdam (RTM) (DR) | H11: 46237 | K11: 36 | L11: =+COUNT(M11:FC11) -> 3 | M11: 4 | N11: 63 | O11: 105
A12: =+B12&B12 -> 78664417866441 | B12: 7866441 | C12: PV574EVB-M | D12: 276 | E12: NETHERLANDS | F12: DSV VENLO | G12: DSV Solutions Nederland (VW) | H12: 46232 | K12: 120 | L12: =+COUNT(M12:FC12) -> 10 | M12: 5 | N12: 7 | O12: 9 | P12: 11 | Q12: 12 | R12: 14 | S12: 16 | T12: 18 | U12: 19 | V12: 21
A13: =+B13&B13 -> 78664447866444 | B13: 7866444 | C13: GC574EVB-M | D13: 282 | E13: NETHERLANDS | F13: DSV VENLO | G13: DSV Solutions Nederland (VW) | H13: 46232 | I13: 46233 | J13: 46234 | K13: 252 | L13: =+COUNT(M13:FC13) -> 22 | M13: 1 | N13: 2 | O13: 3 | P13: 5 | Q13: 6 | R13: 7 | S13: 8 | T13: 9 | U13: 10 | V13: 11 | W13: 12 | X13: 13 | Y13: 14 | Z13: 15 | AA13: 16 | AB13: 17 | AC13: 18 | AD13: 20 | AE13: 21 | AF13: 22 | AG13: 23 | AH13: 25
A14: =+B14&B14 -> 78664507866450 | B14: 7866450 | C14: GC574EVG-M | D14: 1200 | E14: NETHERLANDS | F14: DSV VENLO | G14: DSV Solutions Nederland (VW) | H14: 46231 | K14: 336 | L14: =+COUNT(M14:FC14) -> 28 | M14: 1 | N14: 19 | O14: 21 | P14: 22 | Q14: 23 | R14: 25 | S14: 26 | T14: 27 | U14: 34 | V14: 38 | W14: 39 | X14: 40 | Y14: 41 | Z14: 42 | AA14: 52 | AB14: 53 | AC14: 54 | AD14: 56 | AE14: 62 | AF14: 63 | AG14: 76 | AH14: 77 | AI14: 78 | AJ14: 79 | AK14: 80 | AL14: 83 | AM14: 85 | AN14: 94
A15: =+B15&B15 -> 78666497866649 | B15: 7866649 | C15: PV574EVG-M | D15: 1200 | E15: NETHERLANDS | F15: DSV VENLO | G15: DSV Solutions Nederland (VW) | H15: 46232 | K15: 96 | L15: =+COUNT(M15:FC15) -> 8 | M15: 3 | N15: 14 | O15: 15 | P15: 53 | Q15: 69 | R15: 78 | S15: 81 | T15: 93
A16: =+B16&B16 -> 78666517866651 | B16: 7866651 | C16: GC574EVG-M | D16: 300 | E16: UNITED KINGDOM | F16: DSV SOLUTIONS LTD | G16: D S V Solutions Ltd (UW) | H16: 46233 | K16: 264 | L16: =+COUNT(M16:FC16) -> 23 | M16: 1 | N16: 2 | O16: 3 | P16: 4 | Q16: 5 | R16: 6 | S16: 8 | T16: 9 | U16: 10 | V16: 11 | W16: 12 | X16: 14 | Y16: 15 | Z16: 16 | AA16: 17 | AB16: 18 | AC16: 19 | AD16: 20 | AE16: 21 | AF16: 22 | AG16: 23 | AH16: 24 | AI16: 25
A17: =+B17&B17 -> 78666557866655 | B17: 7866655 | C17: P204L8K2-M | D17: 1278 | E17: NETHERLANDS | F17: DSV VENLO | G17: DSV Solutions Nederland (VW) | H17: 46237 | K17: 612 | L17: =+COUNT(M17:FC17) -> 51 | M17: 1 | N17: 2 | O17: 3 | P17: 4 | Q17: 5 | R17: 9 | S17: 10 | T17: 14 | U17: 15 | V17: 16 | W17: 17 | X17: 19 | Y17: 26 | Z17: 27 | AA17: 28 | AB17: 31 | AC17: 38 | AD17: 39 | AE17: 40 | AF17: 45 | AG17: 46 | AH17: 47 | AI17: 48 | AJ17: 49 | AK17: 55 | AL17: 57 | AM17: 58 | AN17: 59 | AO17: 62 | AP17: 66 | AQ17: 67 | AR17: 68 | AS17: 69 | AT17: 70 | AU17: 73 | AV17: 75 | AW17: 76 | AX17: 77 | AY17: 78 | AZ17: 84 | BA17: 85 | BB17: 86 | BC17: 87 | BD17: 88 | BE17: 89 | BF17: 90 | BG17: 95 | BH17: 97 | BI17: 98 | BJ17: 99 | BK17: 100
A18: =+B18&B18 -> 78666617866661 | B18: 7866661 | C18: P204L9VE-M | D18: 1218 | E18: NETHERLANDS | F18: DSV VENLO | G18: DSV Solutions Nederland (VW) | H18: 46238 | K18: 144 | L18: =+COUNT(M18:FC18) -> 12 | M18: 1 | N18: 2 | O18: 9 | P18: 13 | Q18: 22 | R18: 30 | S18: 36 | T18: 43 | U18: 58 | V18: 69 | W18: 77 | X18: 78
A19: =+B19&B19 -> 78667827866782 | B19: 7866782 | C19: PV574EVE-M | D19: 276 | E19: NETHERLANDS | F19: DSV VENLO | G19: DSV Solutions Nederland (VW) | H19: 46233 | K19: 78 | L19: =+COUNT(M19:FC19) -> 7 | M19: 1 | N19: 3 | O19: 12 | P19: 15 | Q19: 16 | R19: 20 | S19: 22
A20: =+B20&B20 -> 78667967866796 | B20: 7866796 | C20: PV574EVG-M | D20: 288 | E20: UNITED KINGDOM | F20: DSV SOLUTIONS LTD | G20: D S V Solutions Ltd (UW) | H20: 46234 | K20: 48 | L20: =+COUNT(M20:FC20) -> 4 | M20: 5 | N20: 10 | O20: 18 | P20: 21
A21: =+B21&B21 -> 78668027866802 | B21: 7866802 | C21: P204L8K2-M | D21: 288 | E21: UNITED KINGDOM | F21: DSV SOLUTIONS LTD | G21: D S V Solutions Ltd (UW) | H21: 46226 | I21: 46226 | J21: 46227 | K21: 288 | L21: =+COUNT(M21:FC21) -> 26 | M21: 1 | N21: 2 | O21: 3 | P21: 4 | Q21: 5 | R21: 6 | S21: 7 | T21: 8 | U21: 9 | V21: 10 | W21: 11 | X21: 12 | Y21: 13 | Z21: 14 | AA21: 15 | AB21: 16 | AC21: 17 | AD21: 18 | AE21: 19 | AF21: 20 | AG21: 21 | AH21: 22 | AI21: 23 | AJ21: 24 | AK21: 25 | AL21: 26
A22: =+B22&B22 -> 78668147866814 | B22: 7866814 | C22: P204L9VE-M | D22: 330 | E22: UNITED KINGDOM | F22: DSV SOLUTIONS LTD | G22: D S V Solutions Ltd (UW) | H22: 46226 | I22: 46227 | J22: 46227 | K22: 252 | L22: =+COUNT(M22:FC22) -> 23 | M22: 1 | N22: 2 | O22: 3 | P22: 4 | Q22: 5 | R22: 6 | S22: 8 | T22: 10 | U22: 12 | V22: 13 | W22: 15 | X22: 16 | Y22: 18 | Z22: 19 | AA22: 20 | AB22: 21 | AC22: 22 | AD22: 23 | AE22: 24 | AF22: 26 | AG22: 27 | AH22: 29 | AI22: 31
A23: =+B23&B23 -> 78668447866844 | B23: 7866844 | C23: GC574EVE-M | D23: 282 | E23: NETHERLANDS | F23: DSV VENLO | G23: DSV Solutions Nederland (VW) | H23: 46232 | I23: 46237 | J23: 46237 | K23: 168 | L23: =+COUNT(M23:FC23) -> 15 | M23: 1 | N23: 3 | O23: 4 | P23: 5 | Q23: 6 | R23: 7 | S23: 9 | T23: 11 | U23: 12 | V23: 16 | W23: 17 | X23: 19 | Y23: 22 | Z23: 23 | AA23: 25
A24: =+B24&B24 -> 78668507866850 | B24: 7866850 | C24: GC574EVW-M | D24: 282 | E24: NETHERLANDS | F24: DSV VENLO | G24: DSV Solutions Nederland (VW) | H24: 46233 | K24: 228 | L24: =+COUNT(M24:FC24) -> 20 | M24: 3 | N24: 4 | O24: 6 | P24: 7 | Q24: 8 | R24: 9 | S24: 10 | T24: 11 | U24: 12 | V24: 13 | W24: 14 | X24: 15 | Y24: 16 | Z24: 17 | AA24: 18 | AB24: 19 | AC24: 20 | AD24: 22 | AE24: 24 | AF24: 25
A25: =+B25&B25 -> 78674057867405 | B25: 7867405 | C25: PC9060BE-M | D25: 600 | E25: GERMANY | F25: ZALANDO | G25: DSV Solutions Nederland (VX) | H25: 46234 | I25: 46238 | J25: 46239 | K25: 150 | L25: =+COUNT(M25:FC25) -> 13 | M25: 4 | N25: 5 | O25: 9 | P25: 14 | Q25: 20 | R25: 25 | S25: 26 | T25: 34 | U25: 35 | V25: 41 | W25: 42 | X25: 43 | Y25: 49
A26: =+B26&B26 -> 78675327867532 | B26: 7867532 | C26: GC9060BE-M | D26: 498 | E26: GERMANY | F26: ZALANDO | G26: DSV Solutions Nederland (VX) | H26: 46238 | K26: 456 | L26: =+COUNT(M26:FC26) -> 40 | M26: 1 | N26: 2 | O26: 3 | P26: 4 | Q26: 5 | R26: 7 | S26: 8 | T26: 9 | U26: 10 | V26: 11 | W26: 13 | X26: 14 | Y26: 15 | Z26: 16 | AA26: 17 | AB26: 18 | AC26: 19 | AD26: 20 | AE26: 21 | AF26: 23 | AG26: 24 | AH26: 25 | AI26: 26 | AJ26: 27 | AK26: 28 | AL26: 29 | AM26: 30 | AN26: 31 | AO26: 32 | AP26: 33 | AQ26: 34 | AR26: 35 | AS26: 36 | AT26: 37 | AU26: 38 | AV26: 39 | AW26: 40 | AX26: 41 | AY26: 42 | AZ26: 43
A27: =+B27&B27 -> 78675427867542 | B27: 7867542 | C27: GC9060GY-M | D27: 498 | E27: GERMANY | F27: ZALANDO | G27: DSV Solutions Nederland (VX) | H27: 46237 | K27: 192 | L27: =+COUNT(M27:FC27) -> 16 | M27: 4 | N27: 5 | O27: 7 | P27: 8 | Q27: 13 | R27: 15 | S27: 16 | T27: 17 | U27: 18 | V27: 24 | W27: 26 | X27: 28 | Y27: 29 | Z27: 34 | AA27: 35 | AB27: 36
A28: =+B28&B28 -> 78679347867934 | B28: 7867934 | C28: GC9060GY-M | D28: 618 | E28: NETHERLANDS | F28: DSV VENLO | G28: DSV Solutions Nederland (VF) | H28: 46237 | K28: 456 | L28: =+COUNT(M28:FC28) -> 38 | M28: 1 | N28: 2 | O28: 3 | P28: 4 | Q28: 5 | R28: 6 | S28: 8 | T28: 9 | U28: 10 | V28: 11 | W28: 12 | X28: 13 | Y28: 14 | Z28: 16 | AA28: 17 | AB28: 18 | AC28: 19 | AD28: 20 | AE28: 23 | AF28: 24 | AG28: 25 | AH28: 26 | AI28: 27 | AJ28: 28 | AK28: 29 | AL28: 30 | AM28: 33 | AN28: 35 | AO28: 36 | AP28: 37 | AQ28: 38 | AR28: 41 | AS28: 42 | AT28: 43 | AU28: 46 | AV28: 47 | AW28: 48 | AX28: 49
A29: =+B29&B29 -> 78683147868314 | B29: 7868314 | C29: GC9060BE-M | D29: 150 | E29: NETHERLANDS | F29: DSV VENLO | G29: DSV Solutions Nederland (VF) | H29: 46238 | I29: 46238 | J29: 46239 | K29: 150 | L29: =+COUNT(M29:FC29) -> 13 | M29: 1 | N29: 2 | O29: 3 | P29: 4 | Q29: 5 | R29: 6 | S29: 7 | T29: 8 | U29: 9 | V29: 10 | W29: 11 | X29: 12 | Y29: 13
A30: =+B30&B30 -> 78684847868484 | B30: 7868484 | C30: P60394T-M | D30: 924 | E30: NETHERLANDS | F30: DSV VENLO | G30: DSV Solutions Nederland (VF) | H30: 46238 | K30: 588 | L30: =+COUNT(M30:FC30) -> 49 | M30: 1 | N30: 2 | O30: 3 | P30: 4 | Q30: 6 | R30: 9 | S30: 10 | T30: 11 | U30: 12 | V30: 14 | W30: 17 | X30: 18 | Y30: 19 | Z30: 20 | AA30: 21 | AB30: 26 | AC30: 27 | AD30: 28 | AE30: 29 | AF30: 31 | AG30: 33 | AH30: 35 | AI30: 36 | AJ30: 37 | AK30: 38 | AL30: 39 | AM30: 43 | AN30: 45 | AO30: 46 | AP30: 47 | AQ30: 48 | AR30: 50 | AS30: 51 | AT30: 55 | AU30: 56 | AV30: 57 | AW30: 58 | AX30: 59 | AY30: 60 | AZ30: 61 | BA30: 63 | BB30: 66 | BC30: 67 | BD30: 68 | BE30: 69 | BF30: 70 | BG30: 71 | BH30: 72 | BI30: 73
A31: =+B31&B31 -> 78685117868511 | B31: 7868511 | C31: PC9060BE-M | D31: 156 | E31: NETHERLANDS | F31: DSV VENLO | G31: DSV Solutions Nederland (VF) | H31: 46234 | I31: 46238 | J31: 46238 | K31: 102 | L31: =+COUNT(M31:FC31) -> 9 | M31: 1 | N31: 3 | O31: 4 | P31: 7 | Q31: 8 | R31: 9 | S31: 10 | T31: 12 | U31: 14
A32: =+B32&B32 -> 78687077868707 | B32: 7868707 | C32: P60399V-M | D32: 1890 | E32: NETHERLANDS | F32: DSV VENLO | G32: DSV Solutions Nederland (VF) | H32: 46239 | K32: 324 | L32: =+COUNT(M32:FC32) -> 27 | M32: 1 | N32: 19 | O32: 20 | P32: 21 | Q32: 37 | R32: 39 | S32: 40 | T32: 56 | U32: 57 | V32: 58 | W32: 59 | X32: 63 | Y32: 73 | Z32: 91 | AA32: 92 | AB32: 94 | AC32: 95 | AD32: 109 | AE32: 110 | AF32: 117 | AG32: 118 | AH32: 123 | AI32: 134 | AJ32: 135 | AK32: 136 | AL32: 137 | AM32: 138
A33: =+B33&B33 -> 78689857868985 | B33: 7868985 | C33: G5749HD-M | D33: 516 | E33: NETHERLANDS | F33: DSV VENLO | G33: DSV Solutions Nederland (VF) | H33: 46233 | K33: 48 | L33: =+COUNT(M33:FC33) -> 4 | M33: 1 | N33: 11 | O33: 15 | P33: 21
A34: =+B34&B34 -> 78689867868986 | B34: 7868986 | C34: G5749UK-M | D34: 528 | E34: NETHERLANDS | F34: DSV VENLO | G34: DSV Solutions Nederland (VF) | H34: 46232 | K34: 132 | L34: =+COUNT(M34:FC34) -> 11 | M34: 9 | N34: 11 | O34: 12 | P34: 13 | Q34: 14 | R34: 23 | S34: 24 | T34: 25 | U34: 31 | V34: 32 | W34: 33
A35: =+B35&B35 -> 78746617874661 | B35: 7874661 | C35: WL515SB3-B | D35: 456 | E35: NETHERLANDS | F35: OTTO GROUP | G35: DSV Solutions Nederland (VX) | H35: 46238 | K35: 216 | L35: =+COUNT(M35:FC35) -> 36 | M35: 7 | N35: 8 | O35: 12 | P35: 13 | Q35: 14 | R35: 17 | S35: 18 | T35: 19 | U35: 23 | V35: 24 | W35: 25 | X35: 26 | Y35: 27 | Z35: 28 | AA35: 29 | AB35: 30 | AC35: 31 | AD35: 32 | AE35: 33 | AF35: 40 | AG35: 41 | AH35: 42 | AI35: 43 | AJ35: 44 | AK35: 45 | AL35: 46 | AM35: 47 | AN35: 48 | AO35: 56 | AP35: 57 | AQ35: 58 | AR35: 59 | AS35: 60 | AT35: 61 | AU35: 62 | AV35: 63
A36: =+B36&B36 -> 78786917878691 | B36: 7878691 | C36: WL515SB3-B | D36: 1926 | E36: NETHERLANDS | F36: DSV VENLO | G36: DSV Solutions Nederland (VF) | H36: 46239 | K36: 756 | L36: =+COUNT(M36:FC36) -> 63 | M36: 1 | N36: 2 | O36: 3 | P36: 7 | Q36: 8 | R36: 9 | S36: 10 | T36: 21 | U36: 22 | V36: 25 | W36: 26 | X36: 27 | Y36: 28 | Z36: 29 | AA36: 30 | AB36: 31 | AC36: 32 | AD36: 33 | AE36: 34 | AF36: 35 | AG36: 56 | AH36: 57 | AI36: 58 | AJ36: 59 | AK36: 60 | AL36: 61 | AM36: 62 | AN36: 63 | AO36: 64 | AP36: 65 | AQ36: 66 | AR36: 67 | AS36: 90 | AT36: 91 | AU36: 92 | AV36: 93 | AW36: 94 | AX36: 95 | AY36: 96 | AZ36: 97 | BA36: 98 | BB36: 124 | BC36: 125 | BD36: 126 | BE36: 127 | BF36: 128 | BG36: 129 | BH36: 130 | BI36: 131 | BJ36: 132 | BK36: 133 | BL36: 134 | BM36: 135 | BN36: 136 | BO36: 137 | BP36: 138 | BQ36: 150 | BR36: 151 | BS36: 152 | BT36: 153 | BU36: 154 | BV36: 155 | BW36: 156
A37: =+B37&B37 -> C132937C132937 | B37: C132937 | C37: GC9060LL-M | D37: 810 | E37: Canada | F37: FOOTLOCKER CANADA (DIV 76) | G37: Directs Canada Virtual (94) | H37: 46226 | K37: 132 | L37: =+COUNT(M37:FC37) -> 11 | M37: 6 | N37: 9 | O37: 15 | P37: 16 | Q37: 23 | R37: 25 | S37: 31 | T37: 42 | U37: 43 | V37: 52 | W37: 53
A38: =+B38&B38 -> C132941C132941 | B38: C132941 | C38: GC9060GY-M | D38: 960 | E38: Canada | F38: FOOTLOCKER CANADA (DIV 76) | G38: Directs Canada Virtual (94) | H38: 46233 | K38: 300 | L38: =+COUNT(M38:FC38) -> 25 | M38: 16 | N38: 17 | O38: 18 | P38: 19 | Q38: 28 | R38: 29 | S38: 39 | T38: 40 | U38: 41 | V38: 42 | W38: 43 | X38: 44 | Y38: 45 | Z38: 53 | AA38: 54 | AB38: 55 | AC38: 56 | AD38: 57 | AE38: 58 | AF38: 65 | AG38: 66 | AH38: 67 | AI38: 68 | AJ38: 69 | AK38: 70
A39: =+B39&B39 -> C132946C132946 | B39: C132946 | C39: G204L9HL-M | D39: 570 | E39: Canada | F39: New Balance Canada | G39: Concord, ON Canada (85) | H39: 46226 | I39: 46232 | J39: 46232 | K39: 300 | L39: =+COUNT(M39:FC39) -> 25 | M39: 1 | N39: 2 | O39: 3 | P39: 7 | Q39: 8 | R39: 9 | S39: 12 | T39: 13 | U39: 14 | V39: 15 | W39: 19 | X39: 20 | Y39: 25 | Z39: 26 | AA39: 27 | AB39: 30 | AC39: 32 | AD39: 35 | AE39: 36 | AF39: 37 | AG39: 38 | AH39: 39 | AI39: 41 | AJ39: 42 | AK39: 43
A40: =+B40&B40 -> H121187H121187 | B40: H121187 | C40: WL574EVG-B | D40: 210 | E40: United Arab Emirates | F40: NEW BALANCE UAE C/O | G40: DIRECT (1) | H40: 46217 | I40: 46238 | J40: 46238 | K40: 174 | L40: =+COUNT(M40:FC40) -> 15 | M40: 1 | N40: 2 | O40: 3 | P40: 4 | Q40: 6 | R40: 7 | S40: 8 | T40: 9 | U40: 10 | V40: 11 | W40: 12 | X40: 13 | Y40: 14 | Z40: 15 | AA40: 17
...

Sheet 090034 FG In Scan History
A1: =+D1&D1 -> POPO | B1: =+D1&C1 -> POARTICLE | C1: ARTICLE | D1: PO | E1: MARKET | F1: CUSTOMER | G1: WAREHOUSE | H1: QTY ORDER | I1: START IN FG | J1: PO# CLOSING DATE | K1: SI DATE | L1: SCAN TIME | M1: QTY IN | N1: NO. CTN
A2: =+D2&D2 -> 78668507866850 | B2: =+D2&C2 -> 7866850GC574EVW-M | C2: GC574EVW-M | D2: 7866850 | E2: NETHERLANDS | F2: DSV VENLO | G2: DSV Solutions Nederland (VW) | H2: 282 | I2: 46233 | J2: 46248 | K2: PASSED 08/14 | L2: 46233.416 | M2: 12 | N2: 6
A3: =+D3&D3 -> 78668507866850 | B3: =+D3&C3 -> 7866850GC574EVW-M | C3: GC574EVW-M | D3: 7866850 | E3: NETHERLANDS | F3: DSV VENLO | G3: DSV Solutions Nederland (VW) | H3: 282 | I3: 46233 | J3: 46248 | K3: PASSED 08/14 | L3: 46233.416 | M3: 12 | N3: 9
A4: =+D4&D4 -> 78668507866850 | B4: =+D4&C4 -> 7866850GC574EVW-M | C4: GC574EVW-M | D4: 7866850 | E4: NETHERLANDS | F4: DSV VENLO | G4: DSV Solutions Nederland (VW) | H4: 282 | I4: 46233 | J4: 46248 | K4: PASSED 08/14 | L4: 46233.416 | M4: 12 | N4: 15
A5: =+D5&D5 -> 78668507866850 | B5: =+D5&C5 -> 7866850GC574EVW-M | C5: GC574EVW-M | D5: 7866850 | E5: NETHERLANDS | F5: DSV VENLO | G5: DSV Solutions Nederland (VW) | H5: 282 | I5: 46233 | J5: 46248 | K5: PASSED 08/14 | L5: 46233.433 | M5: 12 | N5: 4
A6: =+D6&D6 -> 78668507866850 | B6: =+D6&C6 -> 7866850GC574EVW-M | C6: GC574EVW-M | D6: 7866850 | E6: NETHERLANDS | F6: DSV VENLO | G6: DSV Solutions Nederland (VW) | H6: 282 | I6: 46233 | J6: 46248 | K6: PASSED 08/14 | L6: 46233.434 | M6: 12 | N6: 12
A7: =+D7&D7 -> 78668507866850 | B7: =+D7&C7 -> 7866850GC574EVW-M | C7: GC574EVW-M | D7: 7866850 | E7: NETHERLANDS | F7: DSV VENLO | G7: DSV Solutions Nederland (VW) | H7: 282 | I7: 46233 | J7: 46248 | K7: PASSED 08/14 | L7: 46233.45 | M7: 12 | N7: 16
A8: =+D8&D8 -> 78668507866850 | B8: =+D8&C8 -> 7866850GC574EVW-M | C8: GC574EVW-M | D8: 7866850 | E8: NETHERLANDS | F8: DSV VENLO | G8: DSV Solutions Nederland (VW) | H8: 282 | I8: 46233 | J8: 46248 | K8: PASSED 08/14 | L8: 46233.451 | M8: 12 | N8: 10
A9: =+D9&D9 -> 78668507866850 | B9: =+D9&C9 -> 7866850GC574EVW-M | C9: GC574EVW-M | D9: 7866850 | E9: NETHERLANDS | F9: DSV VENLO | G9: DSV Solutions Nederland (VW) | H9: 282 | I9: 46233 | J9: 46248 | K9: PASSED 08/14 | L9: 46233.461 | M9: 12 | N9: 7
A10: =+D10&D10 -> 78668507866850 | B10: =+D10&C10 -> 7866850GC574EVW-M | C10: GC574EVW-M | D10: 7866850 | E10: NETHERLANDS | F10: DSV VENLO | G10: DSV Solutions Nederland (VW) | H10: 282 | I10: 46233 | J10: 46248 | K10: PASSED 08/14 | L10: 46233.461 | M10: 12 | N10: 18
A11: =+D11&D11 -> 78668507866850 | B11: =+D11&C11 -> 7866850GC574EVW-M | C11: GC574EVW-M | D11: 7866850 | E11: NETHERLANDS | F11: DSV VENLO | G11: DSV Solutions Nederland (VW) | H11: 282 | I11: 46233 | J11: 46248 | K11: PASSED 08/14 | L11: 46233.461 | M11: 12 | N11: 13
A12: =+D12&D12 -> 78668507866850 | B12: =+D12&C12 -> 7866850GC574EVW-M | C12: GC574EVW-M | D12: 7866850 | E12: NETHERLANDS | F12: DSV VENLO | G12: DSV Solutions Nederland (VW) | H12: 282 | I12: 46233 | J12: 46248 | K12: PASSED 08/14 | L12: 46233.462 | M12: 12 | N12: 17
A13: =+D13&D13 -> 78668507866850 | B13: =+D13&C13 -> 7866850GC574EVW-M | C13: GC574EVW-M | D13: 7866850 | E13: NETHERLANDS | F13: DSV VENLO | G13: DSV Solutions Nederland (VW) | H13: 282 | I13: 46233 | J13: 46248 | K13: PASSED 08/14 | L13: 46233.468 | M13: 12 | N13: 3
... A548: =+D548&D548 -> 78755567875556 | B548: =+D548&C548 -> 7875556M5742IX-D | C548: M5742IX-D | D548: 7875556 | E548: GREECE | F548: STARTLINE SA | G548: DSV Solutions Nederland (VX) | H548: 762 | I548: 46255 | J548: 46265 | K548: PASSED 09/07 | L548: 46255.738 | M548: 12 | N548: 23
A549: =+D549&D549 -> 78661167866116 | B549: =+D549&C549 -> 7866116GC9060BK-M | C549: GC9060BK-M | D549: 7866116 | E549: POLAND | F549: NEW BALANCE POLAND SP ZOO | G549: Direct Rotterdam (RTM) (DR) | H549: 1998 | I549: 46256 | L549: 46256.371 | M549: 12 | N549: 118
A550: =+D550&D550 -> 78661167866116 | B550: =+D550&C550 -> 7866116GC9060BK-M | C550: GC9060BK-M | D550: 7866116 | E550: POLAND | F550: NEW BALANCE POLAND SP ZOO | G550: Direct Rotterdam (RTM) (DR) | H550: 1998 | I550: 46256 | L550: 46256.394 | M550: 12 | N550: 45
A551: =+D551&D551 -> 78661167866116 | B551: =+D551&C551 -> 7866116GC9060BK-M | C551: GC9060BK-M | D551: 7866116 | E551: POLAND | F551: NEW BALANCE POLAND SP ZOO | G551: Direct Rotterdam (RTM) (DR) | H551: 1998 | I551: 46256 | L551: 46256.397 | M551: 12 | N551: 117
A552: =+D552&D552 -> 78661167866116 | B552: =+D552&C552 -> 7866116GC9060BK-M | C552: GC9060BK-M | D552: 7866116 | E552: POLAND | F552: NEW BALANCE POLAND SP ZOO | G552: Direct Rotterdam (RTM) (DR) | H552: 1998 | I552: 46256 | L552: 46256.414 | M552: 12 | N552: 119
A553: =+D553&D553 -> 78661167866116 | B553: =+D553&C553 -> 7866116GC9060BK-M | C553: GC9060BK-M | D553: 7866116 | E553: POLAND | F553: NEW BALANCE POLAND SP ZOO | G553: Direct Rotterdam (RTM) (DR) | H553: 1998 | I553: 46256 | L553: 46256.423 | M553: 12 | N553: 69
A554: =+D554&D554 -> 78661167866116 | B554: =+D554&C554 -> 7866116GC9060BK-M | C554: GC9060BK-M | D554: 7866116 | E554: POLAND | F554: NEW BALANCE POLAND SP ZOO | G554: Direct Rotterdam (RTM) (DR) | H554: 1998 | I554: 46256 | L554: 46256.427 | M554: 12 | N554: 26
A555: =+D555&D555 -> 78661167866116 | B555: =+D555&C555 -> 7866116GC9060BK-M | C555: GC9060BK-M | D555: 7866116 | E555: POLAND | F555: NEW BALANCE POLAND SP ZOO | G555: Direct Rotterdam (RTM) (DR) | H555: 1998 | I555: 46256 | L555: 46256.432 | M555: 12 | N555: 121
A556: =+D556&D556 -> 78661167866116 | B556: =+D556&C556 -> 7866116GC9060BK-M | C556: GC9060BK-M | D556: 7866116 | E556: POLAND | F556: NEW BALANCE POLAND SP ZOO | G556: Direct Rotterdam (RTM) (DR) | H556: 1998 | I556: 46256 | L556: 46256.432 | M556: 12 | N556: 65
A557: =+D557&D557 -> 78661167866116 | B557: =+D557&C557 -> 7866116GC9060BK-M | C557: GC9060BK-M | D557: 7866116 | E557: POLAND | F557: NEW BALANCE POLAND SP ZOO | G557: Direct Rotterdam (RTM) (DR) | H557: 1998 | I557: 46256 | L557: 46256.433 | M557: 12 | N557: 25
A558: =+D558&D558 -> 78661167866116 | B558: =+D558&C558 -> 7866116GC9060BK-M | C558: GC9060BK-M | D558: 7866116 | E558: POLAND | F558: NEW BALANCE POLAND SP ZOO | G558: Direct Rotterdam (RTM) (DR) | H558: 1998 | I558: 46256 | L558: 46256.438 | M558: 12 | N558: 123
A559: =+D559&D559 -> 78661167866116 | B559: =+D559&C559 -> 7866116GC9060BK-M | C559: GC9060BK-M | D559: 7866116 | E559: POLAND | F559: NEW BALANCE POLAND SP ZOO | G559: Direct Rotterdam (RTM) (DR) | H559: 1998 | I559: 46256 | L559: 46256.441 | M559: 12 | N559: 46
A560: =+D560&D560 -> 78661167866116 | B560: =+D560&C560 -> 7866116GC9060BK-M | C560: GC9060BK-M | D560: 7866116 | E560: POLAND | F560: NEW BALANCE POLAND SP ZOO | G560: Direct Rotterdam (RTM) (DR) | H560: 1998 | I560: 46256 | L560: 46256.445 | M560: 12 | N560: 120
... A582: =+D582&D582 -> 78661167866116 | B582: =+D582&C582 -> 7866116GC9060BK-M | C582: GC9060BK-M | D582: 7866116 | E582: POLAND | F582: NEW BALANCE POLAND SP ZOO | G582: Direct Rotterdam (RTM) (DR) | H582: 1998 | I582: 46256 | L582: 46256.501 | M582: 12 | N582: 126
A583: =+D583&D583 -> H176740H176740 | B583: =+D583&C583 -> H176740M5748EK-D | C583: M5748EK-D | D583: H176740 | E583: India | F583: INDEV INFRA PRIVATE LIMITED | G583: 0 | H583: 2622 | I583: 46256 | J583: 46286 | K583: PASSED 09/24 | L583: 46256.393 | M583: 12 | N583: 42
A584: =+D584&D584 -> H176740H176740 | B584: =+D584&C584 -> H176740M5748EK-D | C584: M5748EK-D | D584: H176740 | E584: India | F584: INDEV INFRA PRIVATE LIMITED | G584: 0 | H584: 2622 | I584: 46256 | J584: 46286 | K584: PASSED 09/24 | L584: 46256.4 | M584: 12 | N584: 173
A585: =+D585&D585 -> H176740H176740 | B585: =+D585&C585 -> H176740M5748EK-D | C585: M5748EK-D | D585: H176740 | E585: India | F585: INDEV INFRA PRIVATE LIMITED | G585: 0 | H585: 2622 | I585: 46256 | J585: 46286 | K585: PASSED 09/24 | L585: 46256.408 | M585: 12 | N585: 39
A586: =+D586&D586 -> H176740H176740 | B586: =+D586&C586 -> H176740M5748EK-D | C586: M5748EK-D | D586: H176740 | E586: India | F586: INDEV INFRA PRIVATE LIMITED | G586: 0 | H586: 2622 | I586: 46256 | J586: 46286 | K586: PASSED 09/24 | L586: 46256.408 | M586: 12 | N586: 105
A587: =+D587&D587 -> H176740H176740 | B587: =+D587&C587 -> H176740M5748EK-D | C587: M5748EK-D | D587: H176740 | E587: India | F587: INDEV INFRA PRIVATE LIMITED | G587: 0 | H587: 2622 | I587: 46256 | J587: 46286 | K587: PASSED 09/24 | L587: 46256.409 | M587: 12 | N587: 43
A588: =+D588&D588 -> H176740H176740 | B588: =+D588&C588 -> H176740M5748EK-D | C588: M5748EK-D | D588: H176740 | E588: India | F588: INDEV INFRA PRIVATE LIMITED | G588: 0 | H588: 2622 | I588: 46256 | J588: 46286 | K588: PASSED 09/24 | L588: 46256.409 | M588: 12 | N588: 5
A589: =+D589&D589 -> H176740H176740 | B589: =+D589&C589 -> H176740M5748EK-D | C589: M5748EK-D | D589: H176740 | E589: India | F589: INDEV INFRA PRIVATE LIMITED | G589: 0 | H589: 2622 | I589: 46256 | J589: 46286 | K589: PASSED 09/24 | L589: 46256.414 | M589: 12 | N589: 44
A590: =+D590&D590 -> H176740H176740 | B590: =+D590&C590 -> H176740M5748EK-D | C590: M5748EK-D | D590: H176740 | E590: India | F590: INDEV INFRA PRIVATE LIMITED | G590: 0 | H590: 2622 | I590: 46256 | J590: 46286 | K590: PASSED 09/24 | L590: 46256.415 | M590: 12 | N590: 6
A591: =+D591&D591 -> H176740H176740 | B591: =+D591&C591 -> H176740M5748EK-D | C591: M5748EK-D | D591: H176740 | E591: India | F591: INDEV INFRA PRIVATE LIMITED | G591: 0 | H591: 2622 | I591: 46256 | J591: 46286 | K591: PASSED 09/24 | L591: 46256.415 | M591: 12 | N591: 175
A592: =+D592&D592 -> H176740H176740 | B592: =+D592&C592 -> H176740M5748EK-D | C592: M5748EK-D | D592: H176740 | E592: India | F592: INDEV INFRA PRIVATE LIMITED | G592: 0 | H592: 2622 | I592: 46256 | J592: 46286 | K592: PASSED 09/24 | L592: 46256.415 | M592: 12 | N592: 8
A593: =+D593&D593 -> H176740H176740 | B593: =+D593&C593 -> H176740M5748EK-D | C593: M5748EK-D | D593: H176740 | E593: India | F593: INDEV INFRA PRIVATE LIMITED | G593: 0 | H593: 2622 | I593: 46256 | J593: 46286 | K593: PASSED 09/24 | L593: 46256.416 | M593: 12 | N593: 106
A594: =+D594&D594 -> H176740H176740 | B594: =+D594&C594 -> H176740M5748EK-D | C594: M5748EK-D | D594: H176740 | E594: India | F594: INDEV INFRA PRIVATE LIMITED | G594: 0 | H594: 2622 | I594: 46256 | J594: 46286 | K594: PASSED 09/24 | L594: 46256.416 | M594: 12 | N594: 104
... A634: =+D634&D634 -> H176740H176740 | B634: =+D634&C634 -> H176740M5748EK-D | C634: M5748EK-D | D634: H176740 | E634: India | F634: INDEV INFRA PRIVATE LIMITED | G634: 0 | H634: 2622 | I634: 46256 | J634: 46286 | K634: PASSED 09/24 | L634: 46256.503 | M634: 12 | N634: 113
...

Sheet Sheet2
A1: 1 | B1: 2 | C1: 3 | D1: 4 | E1: 5 | F1: 6 | G1: 7 | H1: 8
B2: STYLE | C2: NEW PO | D2: WAREHOUSE | E2: CLR WIDTH | F2: MARKET | G2: CUSTOMER | H2: QTY
A6: =+C6&B6&"-"&E6 -> H171717G6032U8-M | B6: G6032U8 | C6: H171717 | D6: DIRECT (1) | E6: M | F6: Serbia and Montenegro | G6: BDS RS. DOO Beograd | H6: 180
A7: =+C7&B7&"-"&E7 -> H171720G6035EQ-M | B7: G6035EQ | C7: H171720 | D7: DIRECT (1) | E7: M | F7: Serbia and Montenegro | G7: BDS RS. DOO Beograd | H7: 156
A8: =+C8&B8&"-"&E8 -> H171727G6037LU-M | B8: G6037LU | C8: H171727 | D8: DIRECT (1) | E8: M | F8: Serbia and Montenegro | G8: BDS RS. DOO Beograd | H8: 408
A9: =+C9&B9&"-"&E9 -> H171778G6033UP-M | B9: G6033UP | C9: H171778 | D9: DIRECT (1) | E9: M | F9: Serbia and Montenegro | G9: BDS RS. DOO Beograd | H9: 144
A10: =+C10&B10&"-"&E10 -> 7873637G6035F4-M | B10: G6035F4 | C10: 7873637 | D10: D S V Solutions (UX) | E10: M | F10: UNITED KINGDOM | G10: Sports Direct Internation | H10: 372
A11: =+C11&B11&"-"&E11 -> 7873785G6035F4-M | B11: G6035F4 | C11: 7873785 | D11: D S V Solutions (UX) | E11: M | F11: UNITED KINGDOM | G11: Sports Direct Internation | H11: 576
A12: =+C12&B12&"-"&E12 -> U146432G6035F4-M | B12: G6035F4 | C12: U146432 | D12: Direct USA Virtual (97) | E12: M | F12: United States | G12: DSW, INC. | H12: 756
A13: =+C13&B13&"-"&E13 -> U146468G6035F4-M | B13: G6035F4 | C13: U146468 | D13: Direct USA Virtual (97) | E13: M | F13: United States | G13: FINISHLINE - MACY'S DIVISION | H13: 858
A14: =+C14&B14&"-"&E14 -> U146469G6035F4-M | B14: G6035F4 | C14: U146469 | D14: Direct USA Virtual (97) | E14: M | F14: United States | G14: FINISHLINE - MACY'S DIVISION | H14: 1242
A15: =+C15&B15&"-"&E15 -> U146477G6035F4-M | B15: G6035F4 | C15: U146477 | D15: Direct USA Virtual (97) | E15: M | F15: United States | G15: EUROSTAR, INC. / WSS | H15: 2400
A16: =+C16&B16&"-"&E16 -> 7873632G6032Z2-M | B16: G6032Z2 | C16: 7873632 | D16: D S V Solutions (UX) | E16: M | F16: UNITED KINGDOM | G16: Sports Direct Internation | H16: 576
A17: =+C17&B17&"-"&E17 -> C134979G6035EQ-M | B17: G6035EQ | C17: C134979 | D17: Concord, ON Canada (85) | E17: M | F17: Canada | G17: New Balance Canada | H17: 48
... A101: =+C101&B101&"-"&E101 -> H176962PV574EVW-M | B101: PV574EVW | C101: H176962 | D101: DIRECT (1) | E101: M | F101: South Africa | G101: NEW BALANCE SOUTH AFRICA (PTY) LTD. | H101: 150
A102: =+C102&B102&"-"&E102 -> 7876950I57425Y-M | B102: I57425Y | C102: 7876950 | D102: Direct Rotterdam (RTM) (DR) | E102: M | F102: POLAND | G102: NEW BALANCE POLAND SP ZOO | H102: 204
A103: =+C103&B103&"-"&E103 -> 7876511I57429D-M | B103: I57429D | C103: 7876511 | D103: Direct Rotterdam (RTM) (DR) | E103: M | F103: POLAND | G103: NEW BALANCE POLAND SP ZOO | H103: 306
A104: =+C104&B104&"-"&E104 -> 7876773I5746W2-M | B104: I5746W2 | C104: 7876773 | D104: Direct Rotterdam (RTM) (DR) | E104: M | F104: POLAND | G104: NEW BALANCE POLAND SP ZOO | H104: 144
A105: =+C105&B105&"-"&E105 -> 7875487GC574EVG-W | B105: GC574EVG | C105: 7875487 | D105: DSV Solutions Nederland (VW) | E105: W | F105: NETHERLANDS | G105: DSV VENLO | H105: 198
A106: =+C106&B106&"-"&E106 -> H176907GC574EVG-M | B106: GC574EVG | C106: H176907 | D106: DIRECT (1) | E106: M | F106: Australia | G106: NEW BALANCE C/O | H106: 144
A107: =+C107&B107&"-"&E107 -> C135219GC574EVW-M | B107: GC574EVW | C107: C135219 | D107: Concord, ON Canada (85) | E107: M | F107: Canada | G107: New Balance Canada | H107: 336
A108: =+C108&B108&"-"&E108 -> U152761GC574EVW-M | B108: GC574EVW | C108: U152761 | D108: Lawrence, Massachusetts - USA (22) | E108: M | F108: United States | G108: NEW BALANCE ATHLETICS, INC. | H108: 2052
A109: =+C109&B109&"-"&E109 -> U152761GC574EVW-W | B109: GC574EVW | C109: U152761 | D109: Lawrence, Massachusetts - USA (22) | E109: W | F109: United States | G109: NEW BALANCE ATHLETICS, INC. | H109: 270
A110: =+C110&B110&"-"&E110 -> U152762PC574EVW-M | B110: PC574EVW | C110: U152762 | D110: Lawrence, Massachusetts - USA (22) | E110: M | F110: United States | G110: NEW BALANCE ATHLETICS, INC. | H110: 618
A111: =+C111&B111&"-"&E111 -> U152762PC574EVW-W | B111: PC574EVW | C111: U152762 | D111: Lawrence, Massachusetts - USA (22) | E111: W | F111: United States | G111: NEW BALANCE ATHLETICS, INC. | H111: 36
A112: =+C112&B112&"-"&E112 -> U152764NW574EVW-M | B112: NW574EVW | C112: U152764 | D112: Lawrence, Massachusetts - USA (22) | E112: M | F112: United States | G112: NEW BALANCE ATHLETICS, INC. | H112: 414
A113: =+C113&B113&"-"&E113 -> U152764NW574EVW-W | B113: NW574EVW | C113: U152764 | D113: Lawrence, Massachusetts - USA (22) | E113: W | F113: United States | G113: NEW BALANCE ATHLETICS, INC. | H113: 366
A114: =+C114&B114&"-"&E114 -> U152764NW574EVW-XW | B114: NW574EVW | C114: U152764 | D114: Lawrence, Massachusetts - USA (22) | E114: XW | F114: United States | G114: NEW BALANCE ATHLETICS, INC. | H114: 66
... A192: =+C192&B192&"-"&E192 -> H190533PV574EVG-W | B192: PV574EVG | C192: H190533 | D192: DIRECT (1) | E192: W | F192: Taiwan | G192: NEW BALANCE TAIWAN, INC | H192: 1008
A193: =+C193&B193&"-"&E193 -> 7866850GC574EVW-M | B193: GC574EVW | C193: 7866850 | D193: DSV Solutions Nederland (VW) | E193: M | F193: NETHERLANDS | G193: DSV VENLO | H193: 282
A194: =+C194&B194&"-"&E194 -> 7866212GC574EVB-M | B194: GC574EVB | C194: 7866212 | D194: Direct Rotterdam (RTM) (DR) | E194: M | F194: POLAND | G194: NEW BALANCE POLAND SP ZOO | H194: 270
A195: =+C195&B195&"-"&E195 -> 7866239GC574EVE-M | B195: GC574EVE | C195: 7866239 | D195: Direct Rotterdam (RTM) (DR) | E195: M | F195: POLAND | G195: NEW BALANCE POLAND SP ZOO | H195: 234
A196: =+C196&B196&"-"&E196 -> 7866225GC574EVG-M | B196: GC574EVG | C196: 7866225 | D196: Direct Rotterdam (RTM) (DR) | E196: M | F196: POLAND | G196: NEW BALANCE POLAND SP ZOO | H196: 234
A197: =+C197&B197&"-"&E197 -> 7866189GC574EVK-M | B197: GC574EVK | C197: 7866189 | D197: Direct Rotterdam (RTM) (DR) | E197: M | F197: POLAND | G197: NEW BALANCE POLAND SP ZOO | H197: 360
A198: =+C198&B198&"-"&E198 -> 7866243GC574EVW-M | B198: GC574EVW | C198: 7866243 | D198: Direct Rotterdam (RTM) (DR) | E198: M | F198: POLAND | G198: NEW BALANCE POLAND SP ZOO | H198: 144
A199: =+C199&B199&"-"&E199 -> 7866883PC574EVW-M | B199: PC574EVW | C199: 7866883 | D199: DSV Solutions Nederland (VW) | E199: M | F199: NETHERLANDS | G199: DSV VENLO | H199: 276
A200: =+C200&B200&"-"&E200 -> 7866406G6035EQ-M | B200: G6035EQ | C200: 7866406 | D200: Direct Rotterdam (RTM) (DR) | E200: M | F200: ITALY | G200: NEW BALANCE ITALY SRL | H200: 420
A201: =+C201&B201&"-"&E201 -> H171722G6037LU-M | B201: G6037LU | C201: H171722 | D201: DIRECT (1) | E201: M | F201: Serbia and Montenegro | G201: BDS RS. DOO Beograd | H201: 228
A202: =+C202&B202&"-"&E202 -> H176945W60336H-B | B202: W60336H | C202: H176945 | D202: DIRECT (1) | E202: B | F202: Switzerland | G202: CHRIS SPORTS AG | H202: 570
A203: =+C203&B203&"-"&E203 -> 7875658W60347S-B | B203: W60347S | C203: 7875658 | D203: DSV Solutions Nederland (VX) | E203: B | F203: GREECE | G203: STARTLINE SA | H203: 306
...
